<robot name="diff_drive">
 <link name="base">
   <visual>
     <origin xyz="0 0 0" rpy="0 0 0"/>
     <geometry>
       <box size="0.420 0.200 0.120"/>
     </geometry>
   </visual>
   <collision>
     <origin xyz="0 0 0" rpy="0 0 0"/>
     <geometry>
       <box size="0.420 0.200 0.120"/>
     </geometry>
   </collision>
   <inertial>
     <mass value="2.0"/>
     <inertia ixx="0.02" ixy="0" ixz="0" iyy="0.02" iyz="0" izz="0.02"/>
   </inertial>
 </link>
  <link name="mid_leg_r">
   <visual>
     <origin xyz="0 0 0" rpy="0 0 0"/>
     <geometry>
       <box size="0.118 0.05 0.041"/>
     </geometry>
   </visual>
   <collision>
     <origin xyz="0 0 0" rpy="0 0 0"/>
     <geometry>
       <box size="0.118 0.05 0.041"/>
     </geometry>
   </collision>
   <inertial>
     <mass value="0.5"/>
     <inertia ixx="0.001" ixy="0" ixz="0" iyy="0.001" iyz="0" izz="0.001"/>
   </inertial>
 </link>
  <link name="mid_leg_l">
   <visual>
     <origin xyz="0 0 0" rpy="0 0 0"/>
     <geometry>
       <box size="0.118 0.05 0.041"/>
     </geometry>
   </visual>
   <collision>
     <origin xyz="0 0 0" rpy="0 0 0"/>
     <geometry>
       <box size="0.118 0.05 0.041"/>
     </geometry>
   </collision>
   <inertial>
     <mass value="0.5"/>
     <inertia ixx="0.001" ixy="0" ixz="0" iyy="0.001" iyz="0" izz="0.001"/>
   </inertial>
 </link>
  <joint name="base_to_lleg" type="revolute">
    <origin xyz="0 -0.12 0" rpy="1.5708 0 0"/>
    <parent link="base"/>
    <child link="mid_leg_l"/>
    <axis xyz = "0 0 1"/>
    <limit effort="10.0" velocity="5.0" lower="-0.5" upper="0.5"/>
  </joint>
    <joint name="base_to_rleg" type="revolute">
    <origin xyz="0 0.12 0" rpy="1.5708 0 0"/>
    <parent link="base"/>
    <child link="mid_leg_r"/>
    <axis xyz = "0 0 1"/>
    <limit effort="10.0" velocity="5.0" lower="-0.5" upper="0.5"/>
  </joint>
  <link name="front_wheel_r">
   <visual>
     <origin xyz="0 0 0" rpy="0 0 0"/>
     <geometry>
       <cylinder length="0.067" radius="0.079"/>
     </geometry>
   </visual>
   <collision>
     <origin xyz="0 0 0" rpy="0 0 0"/>
     <geometry>
       <cylinder length="0.067" radius="0.079"/>
     </geometry>
   </collision>
   <inertial>
     <mass value="1.5"/>
     <inertia ixx="0.002" ixy="0" ixz="0" iyy="0.002" iyz="0" izz="0.002"/>
   </inertial>
 </link>
  <link name="front_leg_r">
   <visual>
     <origin xyz="0 0 0" rpy="0 0 0"/>
     <geometry>
       <box size="0.245 0.045 0.041"/>
     </geometry>
   </visual>
   <collision>
     <origin xyz="0 0 0" rpy="0 0 0"/>
     <geometry>
       <box size="0.245 0.045 0.041"/>
     </geometry>
   </collision>
   <inertial>
     <mass value="0.5"/>
     <inertia ixx="0.001" ixy="0" ixz="0" iyy="0.001" iyz="0" izz="0.001"/>
   </inertial>
 </link>
  <link name="back_wheel_r">
   <visual>
     <origin xyz="0 0 0" rpy="0 0 0"/>
     <geometry>
       <cylinder length="0.067" radius="0.079"/>
     </geometry>
   </visual>
   <collision>
     <origin xyz="0 0 0" rpy="0 0 0"/>
     <geometry>
       <cylinder length="0.067" radius="0.079"/>
     </geometry>
   </collision>
   <inertial>
     <mass value="1.5"/>
     <inertia ixx="0.002" ixy="0" ixz="0" iyy="0.002" iyz="0" izz="0.002"/>
   </inertial>
 </link>
  <link name="back_leg_r">
   <visual>
     <origin xyz="0 0 0" rpy="0 0 0"/>
     <geometry>
       <box size="0.245 0.045 0.041"/>
     </geometry>
   </visual>
   <collision>
     <origin xyz="0 0 0" rpy="0 0 0"/>
     <geometry>
       <box size="0.245 0.045 0.041"/>
     </geometry>
   </collision>
   <inertial>
     <mass value="0.5"/>
     <inertia ixx="0.001" ixy="0" ixz="0" iyy="0.001" iyz="0" izz="0.001"/>
   </inertial>
 </link>
  <joint name="mid_to_front_r" type="fixed">
   <origin xyz="0.12 -0.087 0" rpy="0 0 2.3"/>
   <parent link="mid_leg_r"/>
   <child link="front_leg_r"/>
 </joint>
  <joint name="mid_to_back_r" type="fixed">
   <origin xyz="-0.12 -0.087 0" rpy="0 0 -2.3"/>
   <parent link="mid_leg_r"/>
   <child link="back_leg_r"/>
 </joint>
  <joint name="bkwheel_to_leg_r" type="continuous">
    <origin xyz="0.12 0 -0.0565" rpy="0 0 0"/>
    <parent link="back_leg_r"/>
    <child link="back_wheel_r"/>
    <axis xyz = "0 0 1"/>
  </joint>
  <joint name="frwheel_to_leg_r" type="continuous">
    <origin xyz="-0.12 0 -0.0565" rpy="0 0 0"/>
    <parent link="front_leg_r"/>
    <child link="front_wheel_r"/>
    <axis xyz = "0 0 1"/>
  </joint>
  <link name="front_wheel_l">
   <visual>
     <origin xyz="0 0 0" rpy="0 0 0"/>
     <geometry>
       <cylinder length="0.067" radius="0.079"/>
     </geometry>
   </visual>
   <visual>
     <origin xyz="0 0 0.04" rpy="0 0 0"/>
     <geometry>
       <box size="0.04 0.04 0.001"/>
     </geometry>
     <material name="white">
       <color rgba="1.0 1.0 1.0 1.0"/>
     </material>
   </visual>
   <collision>
     <origin xyz="0 0 0" rpy="0 0 0"/>
     <geometry>
       <cylinder length="0.067" radius="0.079"/>
     </geometry>
   </collision>
   <inertial>
     <mass value="1.5"/>
     <inertia ixx="0.002" ixy="0" ixz="0" iyy="0.002" iyz="0" izz="0.002"/>
   </inertial>
 </link>
  <link name="front_leg_l">
   <visual>
     <origin xyz="0 0 0" rpy="0 0 0"/>
     <geometry>
       <box size="0.245 0.045 0.041"/>
     </geometry>
   </visual>
   <collision>
     <origin xyz="0 0 0" rpy="0 0 0"/>
     <geometry>
       <box size="0.245 0.045 0.041"/>
     </geometry>
   </collision>
   <inertial>
     <mass value="0.5"/>
     <inertia ixx="0.001" ixy="0" ixz="0" iyy="0.001" iyz="0" izz="0.001"/>
   </inertial>
 </link>
  <link name="back_wheel_l">
   <visual>
     <origin xyz="0 0 0" rpy="0 0 0"/>
     <geometry>
       <cylinder length="0.067" radius="0.079"/>
     </geometry>
   </visual>
   <collision>
     <origin xyz="0 0 0" rpy="0 0 0"/>
     <geometry>
       <cylinder length="0.067" radius="0.079"/>
     </geometry>
   </collision>
   <inertial>
     <mass value="1.5"/>
     <inertia ixx="0.002" ixy="0" ixz="0" iyy="0.002" iyz="0" izz="0.002"/>
   </inertial>
 </link>
  <link name="back_leg_l">
   <visual>
     <origin xyz="0 0 0" rpy="0 0 0"/>
     <geometry>
       <box size="0.245 0.045 0.041"/>
     </geometry>
   </visual>
   <collision>
     <origin xyz="0 0 0" rpy="0 0 0"/>
     <geometry>
       <box size="0.245 0.045 0.041"/>
     </geometry>
   </collision>
   <inertial>
     <mass value="0.5"/>
     <inertia ixx="0.001" ixy="0" ixz="0" iyy="0.001" iyz="0" izz="0.001"/>
   </inertial>
 </link>
  <joint name="bkwheel_to_leg_l" type="continuous">
    <origin xyz="0.12 0 0.0565" rpy="0 0 0"/>
    <parent link="back_leg_l"/>
    <child link="back_wheel_l"/>
      <axis xyz = "0 0 1"/>
  </joint>
  <joint name="frwheel_to_leg_l" type="continuous">
    <origin xyz="-0.12 0 0.0565" rpy="0 0 0"/>
    <parent link="front_leg_l"/>
    <child link="front_wheel_l"/>
    <axis xyz = "0 0 1"/>
  </joint>
  <joint name="mid_to_front_l" type="fixed">
   <origin xyz="0.12 -0.087 0" rpy="0 0 2.3"/>
   <parent link="mid_leg_l"/>
   <child link="front_leg_l"/>
 </joint>
  <joint name="mid_to_back_l" type="fixed">
   <origin xyz="-0.12 -0.087 0" rpy="0 0 -2.3"/>
   <parent link="mid_leg_l"/>
   <child link="back_leg_l"/>
 </joint>
  <!-- Friction-->
  <!-- <gazebo reference="front_wheel_r">
    <mu1>10.0</mu1>
    <mu2>10.0</mu2>
    <kp>1000000.0</kp>
    <kd>100.0</kd>
    <minDepth>0.001</minDepth>
    <maxVel>1.0</maxVel>
    <fdir1>0 1 0</fdir1>
  </gazebo>

  <gazebo reference="back_wheel_r">
    <mu1>10.0</mu1>
    <mu2>10.0</mu2>
    <kp>1000000.0</kp>
    <kd>100.0</kd>
    <minDepth>0.001</minDepth>
    <maxVel>1.0</maxVel>
    <fdir1>0 1 0</fdir1>
  </gazebo>

  <gazebo reference="front_wheel_l">
    <mu1>10.0</mu1>
    <mu2>10.0</mu2>
    <kp>1000000.0</kp>
    <kd>100.0</kd>
    <minDepth>0.001</minDepth>
    <maxVel>1.0</maxVel>
    <fdir1>0 1 0</fdir1>
  </gazebo>

  <gazebo reference="back_wheel_l">
    <mu1>10.0</mu1>
    <mu2>10.0</mu2>
    <kp>1000000.0</kp>
    <kd>100.0</kd>
    <minDepth>0.001</minDepth>
    <maxVel>1.0</maxVel>
    <fdir1>0 1 0</fdir1>
  </gazebo> -->

  <!-- LiDAR Link -->
  <link name="lidar_link">
    <visual>
      <origin xyz="0 0 0" rpy="0 0 0"/>
      <geometry>
        <cylinder length="0.05" radius="0.03"/>
      </geometry>
      <material name="black">
        <color rgba="0.0 0.0 0.0 1.0"/>
      </material>
    </visual>
    <collision>
      <origin xyz="0 0 0" rpy="0 0 0"/>
      <geometry>
        <cylinder length="0.05" radius="0.03"/>
      </geometry>
    </collision>
    <inertial>
      <mass value="0.1"/>
      <inertia ixx="0.0001" ixy="0" ixz="0" iyy="0.0001" iyz="0" izz="0.0001"/>
    </inertial>
  </link>
  <!-- Joint connecting LiDAR to robot base -->
  <joint name="base_to_lidar" type="fixed">
    <origin xyz="0.15 0 0.07" rpy="0 0 0"/>
    <parent link="base"/>
    <child link="lidar_link"/>
  </joint>

 <gazebo>
  <!-- First, include the sensors system plugin -->
  <plugin
    filename="libignition-gazebo-sensors-system.so"
    name="ignition::gazebo::systems::Sensors">
    <render_engine>ogre2</render_engine>
  </plugin>

  <!-- Configure the LiDAR sensor -->
  <sensor name="lidar_sensor" type="gpu_lidar" reference="lidar_link">
    <topic>scan</topic>
    <update_rate>10</update_rate>
    <lidar>
      <scan>
        <horizontal>
          <samples>360</samples>
          <resolution>1</resolution>
          <min_angle>-3.14159</min_angle>
          <max_angle>3.14159</max_angle>
        </horizontal>
        <vertical>
          <samples>1</samples>
          <resolution>1</resolution>
          <min_angle>0</min_angle>
          <max_angle>0</max_angle>
        </vertical>
      </scan>
      <range>
        <min>0.10</min>
        <max>10.0</max>
        <resolution>0.01</resolution>
      </range>
      <noise>
        <type>gaussian</type>
        <mean>0.0</mean>
        <stddev>0.01</stddev>
      </noise>
    </lidar>
    <visualize>true</visualize>
  </sensor>

  <plugin
    filename="libignition-gazebo-joint-controller-system.so"
    name="ignition::gazebo::systems::JointController">
    <joint_name>frwheel_to_leg_r</joint_name>
    <use_velocity_commands>true</use_velocity_commands>
    <initial_velocity>1.0</initial_velocity>
    <topic>/model/diff_drive/joint/frwheel_to_leg_r/cmd_vel</topic>
  </plugin>

  <plugin
    filename="libignition-gazebo-joint-controller-system.so"
    name="ignition::gazebo::systems::JointController">
    <joint_name>frwheel_to_leg_l</joint_name>
    <use_velocity_commands>true</use_velocity_commands>
    <initial_velocity>1.0</initial_velocity>
    <topic>/model/diff_drive/joint/frwheel_to_leg_l/cmd_vel</topic>
  </plugin>
  
  <plugin
    filename="libignition-gazebo-joint-controller-system.so"
    name="ignition::gazebo::systems::JointController">
    <joint_name>bkwheel_to_leg_r</joint_name>
    <initial_velocity>1.0</initial_velocity>
    <use_velocity_commands>true</use_velocity_commands>
    <topic>/model/diff_drive/joint/bkwheel_to_leg_r/cmd_vel</topic>
  </plugin>
  
  <plugin
    filename="libignition-gazebo-joint-controller-system.so"
    name="ignition::gazebo::systems::JointController">
    <joint_name>bkwheel_to_leg_l</joint_name>
    <use_velocity_commands>true</use_velocity_commands>
    <initial_velocity>1.0</initial_velocity>
    <topic>/model/diff_drive/joint/bkwheel_to_leg_l/cmd_vel</topic>
  </plugin>

 </gazebo>
</robot>